I'm sorry, but an uncaught exception occurred.

While running game code:
  File "game/script.rpy", line 62, in script
    $ currentItems = itemsTurn[turnNumber]
  File "game/script.rpy", line 62, in <module>
    $ currentItems = itemsTurn[turnNumber]
KeyError: 3

-- Full Traceback ------------------------------------------------------------

Full traceback:
  File "game/script.rpy", line 62, in script
    $ currentItems = itemsTurn[turnNumber]
  File "C:\Users\dhend\Desktop\Projects\GameJam\RenPy\renpy-8.2.1-sdk\renpy\ast.py", line 823, in execute
    renpy.python.py_exec_bytecode(self.code.bytecode, self.hide, store=self.store)
  File "C:\Users\dhend\Desktop\Projects\GameJam\RenPy\renpy-8.2.1-sdk\renpy\python.py", line 1178, in py_exec_bytecode
    exec(bytecode, globals, locals)
  File "game/script.rpy", line 62, in <module>
    $ currentItems = itemsTurn[turnNumber]
KeyError: 3

Windows-10-10.0.22631 AMD64
Ren'Py 8.2.1.24030407
Out-Of-Order-VN 1.0
Sun Mar 31 03:55:58 2024
